<mujocoinclude>
  <camera pos="0 0.5 1.5" name="topview" />
  <camera name="corner" mode="fixed" pos="-1.1 -0.4 0.6" xyaxes="-1 1 0 -0.2 -0.2 -1"/>
  <camera name="corner2" fovy="60" mode="fixed" pos="1.3 -0.2 1.1" euler="3.9 2.3 0.6"/>
  <camera name="corner3" fovy="45" mode="fixed" pos="0.9 0 1.5" euler="3.5 2.7 1"/>

  <body name="link_base" pos="0 0.22 0.12" childclass="xarm7">
    <inertial pos="-0.021131 -0.0016302 0.056488" quat="0.696843 0.20176 0.10388 0.680376" mass="0.88556"
      diaginertia="0.00382023 0.00335282 0.00167725"/>
    <geom mesh="link_base" conaffinity="0" contype="0"/>

    <body name="link1" pos="0 0 0.267">
      <inertial pos="-0.0002 0.02905 -0.01233" quat="0.978953 -0.202769 -0.00441617 -0.0227264" mass="2.382"
        diaginertia="0.00569127 0.00533384 0.00293865"/>
      <joint name="joint1" class="size1"/>
      <geom mesh="link1" conaffinity="0" contype="0"/>

      <body name="link2" quat="1 -1 0 0">
        <inertial pos="0.00022 -0.12856 0.01735" quat="0.50198 0.86483 -0.00778841 0.00483285" mass="1.869"
          diaginertia="0.00959898 0.00937717 0.00201315"/>
        <joint name="joint2" range="-2.059 2.0944" class="size1"/>
        <geom mesh="link2"/>

        <body name="link3" pos="0 -0.293 0" quat="1 1 0 0">
          <inertial pos="0.0466 -0.02463 -0.00768" quat="0.913819 0.289775 0.281481 -0.0416455" mass="1.6383"
            diaginertia="0.00351721 0.00294089 0.00195868"/>
          <joint name="joint3" class="size2"/>
          <geom mesh="link3"/>

          <body name="link4" pos="0.0525 0 0" quat="1 1 0 0">
            <inertial pos="0.07047 -0.11575 0.012" quat="0.422108 0.852026 -0.126025 0.282832" mass="1.7269"
              diaginertia="0.00657137 0.00647948 0.00186763"/>
            <joint name="joint4" range="-0.19198 3.927" class="size2"/>
            <geom mesh="link4"/>

            <body name="link5" pos="0.0775 -0.3425 0" quat="1 1 0 0">
              <inertial pos="-0.00032 0.01604 -0.026" quat="0.999311 -0.0304457 0.000577067 0.0212082" mass="1.3203"
                diaginertia="0.00534729 0.00499076 0.0013489"/>
              <joint name="joint5" class="size2"/>
              <geom mesh="link5"/>

              <body name="link6" quat="1 1 0 0">
                <inertial pos="0.06469 0.03278 0.02141" quat="-0.217672 0.772419 0.16258 0.574069" mass="1.325"
                  diaginertia="0.00245421 0.00221646 0.00107273"/>
                <joint name="joint6" range="-1.69297 3.14159" class="size3"/>
                <geom mesh="link6"/>

                <body name="link7" pos="0.076 0.097 0" quat="1 -1 0 0">
                  <inertial pos="0 -0.00677 -0.01098" quat="0.487612 0.512088 -0.512088 0.487612" mass="0.17"
                    diaginertia="0.000132176 9.3e-05 5.85236e-05"/>
                  <joint name="joint7" class="size3"/>
                  <geom material="gray" mesh="end_tool"/>
                  
                  <site name="attachment_site" pos="0 0 0" quat="1 0 0 0"/>

                  <body name="hand" pos="0 0 0.05" quat="1 0 -1 0">
                    <camera name="behindGripper" mode="track" pos="0 0 -0.5" quat="0 1 0 0" fovy="60" />
                    <camera name="gripperPOV" mode="track" pos="0 -0.1 0" quat="-1 -1.3 0 0" fovy="90" />

                    <site name="endEffector" pos="0.04 0 0" size="0.01" rgba='1 1 1 0' />
                    <geom name="rail" type="box" pos="-0.05 0 0" density="7850" size="0.005 0.055 0.005" rgba="0.5 0.5 0.5 1.0" condim="3" friction="2 0.1 0.002" />

                    <body name="rightclaw" pos="0 -0.05 0">
                      <geom class="base_col" name="rightclaw_it" condim="4" margin="0.001" type="box" user="0" pos="0 0 0" size="0.045 0.003 0.015" rgba="1 1 1 1.0" />
                      <joint name="r_close" pos="0 0 0" axis="0 1 0" range= "0 0.04" armature="100" damping="1000" limited="true" type="slide"/>
                      <site name="rightEndEffector" pos="0.045 0 0" size="0.01" rgba="1.0 0.0 0.0 1.0"/>
                      <body name="rightpad" pos="0 .003 0">
                        <geom name="rightpad_geom" condim="4" margin="0.001" type="box" user="0" pos="0 0 0" size="0.045 0.003 0.015" rgba="1 1 1 1.0" solimp="0.95 0.99 0.01" solref="0.01 1" friction="2 0.1 0.002" contype="1" conaffinity="1" mass="1"/>
                      </body>
                    </body>

                    <body name="leftclaw" pos="0 0.05 0">
                      <geom class="base_col" name="leftclaw_it" condim="4" margin="0.001" type="box" user="0" pos="0 0 0" size="0.045 0.003 0.015" rgba="0 1 1 1.0" />
                      <joint name="l_close" pos="0 0 0" axis="0 1 0" range= "-0.03 0" armature="100" damping="1000" limited="true" type="slide"/>
                      <site name="leftEndEffector" pos="0.045 0 0" size="0.01" rgba="1.0 0.0 0.0 1.0"/>
                      <body name="leftpad" pos="0 -.003 0">
                        <geom name="leftpad_geom" condim="4" margin="0.001" type="box" user="0" pos="0 0 0" size="0.045 0.003 0.015" rgba="0 1 1 1.0" solimp="0.95 0.99 0.01" solref="0.01 1" friction="2 0.1 0.002" contype="1" conaffinity="1" />
                      </body>
                    </body>
                  </body>
                </body>
              </body>
            </body>
          </body>
        </body>
      </body>
    </body>
  </body>

  <body mocap="true" name="mocap" pos="0 0 0">
    <geom conaffinity="0" contype="0" pos="0 0 0" rgba="0.0 0.5 0.5 0" size="0.01" type="sphere"></geom>
    <site name="mocap" pos="0 0 0" rgba="0.0 0.5 0.5 0" size="0.01" type="sphere"></site>
  </body>

</mujocoinclude>