<mujocoinclude>
  <camera pos="0 0.5 1.5" name="topview" />
  <camera name="corner" mode="fixed" pos="-1.1 -0.4 0.6" xyaxes="-1 1 0 -0.2 -0.2 -1"/>
  <camera name="corner2" fovy="60" mode="fixed" pos="1.3 -0.2 1.1" euler="3.9 2.3 0.6"/>
  <camera name="corner3" fovy="45" mode="fixed" pos="0.9 0 1.5" euler="3.5 2.7 1"/>

  <body name="base" pos="0 0.12 0.12" childclass="gen3">
    <inertial pos="-0.000648 -0.000166 0.084487" quat="0.999294 0.00139618 -0.0118387 0.035636" mass="1.697"
      diaginertia="0.00462407 0.00449437 0.00207755"/>
    <geom class="visual" mesh="base_link"/>
    <geom class="collision" mesh="base_link" conaffinity="0" contype="0"/>

    <body name="shoulder_link" pos="0 0 0.15643" quat="0 1 0 0">
      <inertial pos="-2.3e-05 -0.010364 -0.07336" quat="0.707051 0.0451246 -0.0453544 0.704263" mass="1.3773"
        diaginertia="0.00488868 0.00457 0.00135132"/>
      <joint name="joint_1" class="large_actuator"/>
      <geom class="visual" mesh="shoulder_link"/>
      <geom class="collision" mesh="shoulder_link" conaffinity="0" contype="0"/>

      <body name="half_arm_1_link" pos="0 0.005375 -0.12838" quat="1 1 0 0">
        <inertial pos="-4.4e-05 -0.09958 -0.013278" quat="0.482348 0.516286 -0.516862 0.483366" mass="1.1636"
          diaginertia="0.0113017 0.011088 0.00102532"/>
        <joint name="joint_2" class="large_actuator" range="-2.24 2.24"/>
        <geom class="visual" mesh="half_arm_1_link"/>
        <geom class="collision" mesh="half_arm_1_link"/>

        <body name="half_arm_2_link" pos="0 -0.21038 -0.006375" quat="1 -1 0 0">
          <inertial pos="-4.4e-05 -0.006641 -0.117892" quat="0.706144 0.0213722 -0.0209128 0.707437" mass="1.1636"
            diaginertia="0.0111633 0.010932 0.00100671"/>
          <joint name="joint_3" class="large_actuator"/>
          <geom class="visual" mesh="half_arm_2_link"/>
          <geom class="collision" mesh="half_arm_2_link"/>

          <body name="forearm_link" pos="0 0.006375 -0.21038" quat="1 1 0 0">
            <inertial pos="-1.8e-05 -0.075478 -0.015006" quat="0.483678 0.515961 -0.515859 0.483455" mass="0.9302"
              diaginertia="0.00834839 0.008147 0.000598606"/>
            <joint name="joint_4" class="large_actuator" range="-2.57 2.57"/>
            <geom class="visual" mesh="forearm_link"/>
            <geom class="collision" mesh="forearm_link"/>

            <body name="spherical_wrist_1_link" pos="0 -0.20843 -0.006375" quat="1 -1 0 0">
              <inertial pos="1e-06 -0.009432 -0.063883" quat="0.703558 0.0707492 -0.0707492 0.703558" mass="0.6781"
                diaginertia="0.00165901 0.001596 0.000346988"/>
              <joint name="joint_5" class="small_actuator"/>
              <geom class="visual" mesh="spherical_wrist_1_link"/>
              <geom class="collision" mesh="spherical_wrist_1_link"/>

              <body name="spherical_wrist_2_link" pos="0 0.00017505 -0.10593" quat="1 1 0 0">
                <inertial pos="1e-06 -0.045483 -0.00965" quat="0.44426 0.550121 -0.550121 0.44426" mass="0.6781"
                  diaginertia="0.00170087 0.001641 0.00035013"/>
                <joint name="joint_6" class="small_actuator" range="-2.09 2.09"/>
                <geom class="visual" mesh="spherical_wrist_2_link"/>
                <geom class="collision" mesh="spherical_wrist_2_link"/>

                <body name="bracelet_link" pos="0 -0.10593 -0.00017505" quat="1 -1 0 0">
                  <inertial pos="0.000281 0.011402 -0.029798" quat="0.394358 0.596779 -0.577293 0.393789" mass="0.5"
                    diaginertia="0.000657336 0.000587019 0.000320645"/>
                  <joint name="joint_7" class="small_actuator"/>
                  <geom class="visual" mesh="bracelet_with_vision_link"/>
                  <geom class="collision" mesh="bracelet_with_vision_link"/>
                  
                  <site name="attachment_site" pos="0 0 -0.0615" quat="1 0 0 0"/>

                  <body name="hand" pos="0 0 -0.1" quat="0.707 0 0.707 0">
                    <camera name="behindGripper" mode="track" pos="0 0 -0.5" quat="0 1 0 0" fovy="60" />
                    <camera name="gripperPOV" mode="track" pos="0 -0.1 0" quat="-1 -1.3 0 0" fovy="90" />

                    <site name="endEffector" pos="0.04 0 0" size="0.01" rgba='1 1 1 0' />
                    <geom name="rail" type="box" pos="-0.05 0 0" density="7850" size="0.005 0.055 0.005" rgba="0.5 0.5 0.5 1.0" condim="3" friction="2 0.1 0.002" />

                    <body name="rightclaw" pos="0 -0.05 0">
                      <geom class="base_col" name="rightclaw_it" condim="4" margin="0.001" type="box" user="0" pos="0 0 0" size="0.045 0.003 0.015" rgba="1 1 1 1.0" />
                      <joint name="r_close" pos="0 0 0" axis="0 1 0" range= "0 0.04" armature="100" damping="1000" limited="true" type="slide"/>
                      <site name="rightEndEffector" pos="0.045 0 0" size="0.01" rgba="1.0 0.0 0.0 1.0"/>
                      <body name="rightpad" pos="0 .003 0">
                        <geom name="rightpad_geom" condim="4" margin="0.001" type="box" user="0" pos="0 0 0" size="0.045 0.003 0.015" rgba="1 1 1 1.0" solimp="0.95 0.99 0.01" solref="0.01 1" friction="2 0.1 0.002" contype="1" conaffinity="1" mass="1"/>
                      </body>
                    </body>

                    <body name="leftclaw" pos="0 0.05 0">
                      <geom class="base_col" name="leftclaw_it" condim="4" margin="0.001" type="box" user="0" pos="0 0 0" size="0.045 0.003 0.015" rgba="0 1 1 1.0" />
                      <joint name="l_close" pos="0 0 0" axis="0 1 0" range= "-0.03 0" armature="100" damping="1000" limited="true" type="slide"/>
                      <site name="leftEndEffector" pos="0.045 0 0" size="0.01" rgba="1.0 0.0 0.0 1.0"/>
                      <body name="leftpad" pos="0 -.003 0">
                        <geom name="leftpad_geom" condim="4" margin="0.001" type="box" user="0" pos="0 0 0" size="0.045 0.003 0.015" rgba="0 1 1 1.0" solimp="0.95 0.99 0.01" solref="0.01 1" friction="2 0.1 0.002" contype="1" conaffinity="1" />
                      </body>
                    </body>
                  </body>
                </body>
              </body>
            </body>
          </body>
        </body>
      </body>
    </body>
  </body>

  <body mocap="true" name="mocap" pos="0 0 0">
    <geom conaffinity="0" contype="0" pos="0 0 0" rgba="0.0 0.5 0.5 0" size="0.01" type="sphere"></geom>
    <site name="mocap" pos="0 0 0" rgba="0.0 0.5 0.5 0" size="0.01" type="sphere"></site>
  </body>

</mujocoinclude>